{
  "comments": [
    {
      "key": {
        "uuid": "286d01a6_d71032eb",
        "filename": "/COMMIT_MSG",
        "patchSetId": 2
      },
      "lineNbr": 9,
      "author": {
        "id": 1263
      },
      "writtenOn": "2019-12-06T09:34:48Z",
      "side": 1,
      "message": "Not true.",
      "range": {
        "startLine": 9,
        "startChar": 15,
        "endLine": 9,
        "endChar": 19
      },
      "revId": "1043fd38d83434d6c4e002c5354a30027988fbfa",
      "serverId": "6d2eb258-4fe2-443e-8a38-ca81da23d4c2",
      "unresolved": true
    },
    {
      "key": {
        "uuid": "9310bef0_774ab9c4",
        "filename": "test/framework.py",
        "patchSetId": 2
      },
      "lineNbr": 575,
      "author": {
        "id": 1263
      },
      "writtenOn": "2019-12-06T09:34:48Z",
      "side": 1,
      "message": "IOError\n\nThat would catch also VppTransportSocketIOError and socket.error.",
      "range": {
        "startLine": 575,
        "startChar": 19,
        "endLine": 575,
        "endChar": 38
      },
      "revId": "1043fd38d83434d6c4e002c5354a30027988fbfa",
      "serverId": "6d2eb258-4fe2-443e-8a38-ca81da23d4c2",
      "unresolved": true
    },
    {
      "key": {
        "uuid": "64bd3a74_36856134",
        "filename": "test/framework.py",
        "patchSetId": 2
      },
      "lineNbr": 575,
      "author": {
        "id": 1496
      },
      "writtenOn": "2019-12-06T12:23:59Z",
      "side": 1,
      "message": "VPPIOError is a base class of VppTransportSocketIOError. If it is not, it was changed in another changeset.  I will update it here if needed.   \n\n\nsocket.error was a subclass of IOError in python2.  As of python3, socket.error is OSError. \nSee: [0][1] \n[0] https://docs.python.org/3/library/socket.html#socket.error\n[1] https://www.python.org/dev/peps/pep-3151/\n\nAre we ok with not catching the python2 socket.error exception for the next month or so until we drop py2 support after the 20.01 release? \n\nThis is a good catch.",
      "parentUuid": "9310bef0_774ab9c4",
      "range": {
        "startLine": 575,
        "startChar": 19,
        "endLine": 575,
        "endChar": 38
      },
      "revId": "1043fd38d83434d6c4e002c5354a30027988fbfa",
      "serverId": "6d2eb258-4fe2-443e-8a38-ca81da23d4c2",
      "unresolved": true
    },
    {
      "key": {
        "uuid": "a4fbd844_2e089764",
        "filename": "test/framework.py",
        "patchSetId": 2
      },
      "lineNbr": 575,
      "author": {
        "id": 1263
      },
      "writtenOn": "2019-12-06T14:49:36Z",
      "side": 1,
      "message": "\u003e VPPIOError is a base class of VppTransportSocketIOError. If it is not, it was changed in another changeset.  I will update it here if needed.\n\nGit blame on current master says nothing has changed since [2]. Were you planning to change the parent class in a Change that did not get merged?\n\n\u003e socket.error was a subclass of IOError in python2.  As of python3, socket.error is OSError. \n\nWe can wrap socket.error into VppTransportSocketIOError here [3].\n\n[2] https://gerrit.fd.io/r/c/vpp/+/16229/3/src/vpp-api/python/vpp_papi/vpp_transport_socket.py\n[3] https://github.com/FDio/vpp/blob/7b22df06fc14b9edf178eaff31d348ba7c360125/src/vpp-api/python/vpp_papi/vpp_transport_socket.py#L95",
      "parentUuid": "64bd3a74_36856134",
      "range": {
        "startLine": 575,
        "startChar": 19,
        "endLine": 575,
        "endChar": 38
      },
      "revId": "1043fd38d83434d6c4e002c5354a30027988fbfa",
      "serverId": "6d2eb258-4fe2-443e-8a38-ca81da23d4c2",
      "unresolved": true
    }
  ]
}