{
  "comments": [
    {
      "unresolved": false,
      "key": {
        "uuid": "b42fe8a9_3620782a",
        "filename": "/PATCHSET_LEVEL",
        "patchSetId": 3
      },
      "lineNbr": 0,
      "author": {
        "id": 2352
      },
      "writtenOn": "2024-01-16T18:58:49Z",
      "side": 1,
      "message": "NB - The error was \"\"\"18:39:57 ERROR: Error cloning remote repo \u0027origin\u0027\"\"\" which is flaky.\n\nThis change was merged successfully, and I don\u0027t think there is any issue.",
      "revId": "4a515d35a8702fafb1119e3dc4f969160b0e4372",
      "serverId": "6d2eb258-4fe2-443e-8a38-ca81da23d4c2"
    }
  ]
}