{
  "comments": [
    {
      "key": {
        "uuid": "396d78fe_96c1e3e7",
        "filename": "test/run_tests.py",
        "patchSetId": 2
      },
      "lineNbr": 426,
      "author": {
        "id": 1496
      },
      "writtenOn": "2018-11-29T15:07:11Z",
      "side": 1,
      "message": "Can you breakout catching the exception like this: https://gerrit.fd.io/r/#/c/16265/ ? \n If not, can you use: except Exception:",
      "range": {
        "startLine": 426,
        "startChar": 4,
        "endLine": 426,
        "endChar": 11
      },
      "revId": "71ef3b21dfc826e904bafd11f16ffe3562c9efb4",
      "serverId": "6d2eb258-4fe2-443e-8a38-ca81da23d4c2",
      "unresolved": false
    }
  ]
}